{"name": "Error when creating a user with data from an already registered user", "status": "passed", "start": 1713109045976, "stop": 1713109046440, "uuid": "b4ab616c-39c3-47e1-8457-7cd8abfa16d9", "historyId": "0d438a4d2f73fd339445316d7a909c3b", "testCaseId": "0d438a4d2f73fd339445316d7a909c3b", "fullName": "tests.test_create_user.TestCreateUser#test_create_user_with_duplicate_data_fail", "labels": [{"name": "parentSuite", "value": "tests"}, {"name": "suite", "value": "test_create_user"}, {"name": "subSuite", "value": "TestCreateUser"}, {"name": "host", "value": "System-Product"}, {"name": "thread", "value": "31366-MainThread"}, {"name": "framework", "value": "pytest"}, {"name": "language", "value": "cpython3"}, {"name": "package", "value": "tests.test_create_user"}]}